Workbook
Name _Hlk127349196: 'Aprovados Recursos do Fundo'!$I$48

Sheet Consolidada com todas as notas
AG1: 204
B2: CONSELHO ESTADUAL DO IDOSO Rua Boa Vista, 170- CEP 01204-001 - São Paulo-SP Fone 11-2763-8122/2763-8035 cei@desenvolvimentosocial.sp.gov.br
B3: ORGANIZAÇÕES SOCIAIS
C4: Protocolo | D4: OSC/Prefeitura | E4: NOME DO PROPONENTE | F4: NOME DO PROJETO | G4: EIXO | H4: VALOR TOTAL DO PROJETO | I4: MUNICÍPIO | J4: DRADS | K4: Responsável - OSC | L4: EMAIL | M4: ENTREGUE DIA | N4: ETAPA da Análise | O4: PENDÊNCIA | P4: OBS | Q4: NOTA Gilberto | R4: NOTA Erica | S4: NOTA Enizal | T4: NOTA Walkyria | U4: NOTA Elisete | V4: NOTA Adriano | W4: NOTA Paulo Albano | X4: NOTA Alexandra | Y4: NOTA Priscila | Z4: NOTA Leila | AA4: NOTA Vanise | AB4: NOTA Jeverson | AC4: NOTA Cristiane | AD4: NOTA Márcio | AF4: Média | AG4: RESULTADO FINAL
B5: 1 | C5: 001/23 | D5: Organização | E5: Associação São Joaquim de Apoio à Maturidade | F5: Centro de Convivência Casa Azul | G5: Eixo I: Promoção, Assistência e Desenvolvimento Social | H5: 370460.32 | I5: Carapicuíba/SP | J5: DRADS SPO EM OSASCO | K5: Claudia Regina Ferreira | L5: saojoaquim@saojoaquim.org.br | M5: 45279 | N5: Classificado | Q5: 318 | R5: 244 | S5: 265 | T5: 247 | AE5: =COUNT(Q5:AD5) -> 4 | AF5: =AVERAGE(Q5:AD5) -> 268.5 | AG5: =IF(AF5>=$AG$1,"APROVADO","REPROVADO") -> APROVADO
B6: 2 | C6: 002/23 | D6: Organização | E6: Irmandade Padre Emanoel | F6: CriaMais - Sáude e Arte para Pessoa Idosa | G6: - | H6: 45000 | I6: Palmeira d'Oeste/SP | J6: DRADS FERNANDÓPOLIS | K6: Ludimila Bartolomeu Rodrigues | L6: lardosidosdedalas@hotmail.com | M6: 45313 | N6: Classificado | Q6: 297 | Z6: 310 | AB6: 286 | AC6: 327 | AE6: =COUNT(Q6:AD6) -> 4 | AF6: =AVERAGE(Q6:AD6) -> 305 | AG6: =IF(AF6>=$AG$1,"APROVADO","REPROVADO") -> APROVADO
B7: 3 | C7: 003/23 | D7: Prefeitura | E7: Municipal de Palmeira D'Oeste | F7: Idoso 100% Ativo – Hidroginastica | G7: Eixo I: Promoção, Assistência e Desenvolvimento Social | H7: 84000 | I7: Palmeira D'Oeste | J7: DRADS FERNANDÓPOLIS | K7: Lucinele Gabaldi Bertolassi | L7: pmpalmeira@ig.com.br | M7: 45282 | N7: Pré-Classificado | O7: Plano de trabalho sem n° de páginas | Q7: 321 | R7: 157 | AB7: 325 | AE7: =COUNT(Q7:AD7) -> 3 | AF7: =AVERAGE(Q7:AD7) -> 267.66667 | AG7: =IF(AF7>=$AG$1,"APROVADO","REPROVADO") -> APROVADO
B8: 4 | C8: 004/23 | D8: Organização | E8: Santa Casa de Misericordia de Presidente Prudente | F8: Tratamento Oftalmológico | G8: Eixo II: Sáude | H8: 1000000 | I8: Presidente Prudente/SP | J8: DRADS ALTA SOROCABANA EM PRESIDENTE PRUDENTE | K8: William Boscoli Ribeiro | L8: analista.adm@santacasaprudente.org.br | M8: 45281 | N8: Pré-Classificado | O8: Plano de Trabalho sem n° de páginas | Q8: 312 | S8: 275 | T8: 299 | AE8: =COUNT(Q8:AD8) -> 3 | AF8: =AVERAGE(Q8:AD8) -> 295.33333 | AG8: =IF(AF8>=$AG$1,"APROVADO","REPROVADO") -> APROVADO
B9: 5 | C9: 005/23 | D9: Organização | E9: Associação Santo Agostinho -ASA | F9: Saber Mais, Viver Mais | G9: Eixo III: Educação | H9: 341605 | I9: São Paulo/SP | J9: DRADS CAPITAL EM SÃO PAULO | K9: Thais Certain | L9: thais.certain@asatransforma.org.br | M9: 45288 | N9: Classificado | Q9: 272 | R9: 203 | S9: 269 | T9: 290 | AE9: =COUNT(Q9:AD9) -> 4 | AF9: =AVERAGE(Q9:AD9) -> 258.5 | AG9: =IF(AF9>=$AG$1,"APROVADO","REPROVADO") -> APROVADO
B10: 6 | C10: 006/23 | D10: Organização | E10: Congregação Israelita Paulista | F10: Núcleo de Convivência da Maturidade | G10: Eixo I: Promoção, Assistência e Desenvolvimento Social | H10: 523070 | I10: São Paulo/SP | J10: DRADS CAPITAL EM SÃO PAULO | K10: Laura Feldman | L10: acaosocial@cip.org.br | M10: 45288 | N10: Desclassificado | O10: Plano de Trabalho sem Rubricar | AF10: =AVERAGE(Q10:AD10) -> #DIV/0! | AG10: =IF(AF10>=$AG$1,"APROVADO","REPROVADO") -> #DIV/0!
B11: 7 | C11: 007/23 | D11: Organização | E11: Associação de Apoio ao Paciente Renal Cronico e Transplantado -Carim | F11: Saúde e Movimento | G11: - | H11: 364980 | I11: Presidente Prudente/SP | J11: DRADS ALTA SOROCABANA EM PRESIDENTE PRUDENTE | K11: Sumaia Cristina Zahra Zakir Pereira | L11: carimprudente@yahoo.com. br | M11: 45289 | N11: Pré-Classificado | O11: Falta de Informação do envelope | P11: Doc Word | Q11: 340 | S11: 245 | T11: 290 | AE11: =COUNT(Q11:AD11) -> 3 | AF11: =AVERAGE(Q11:AD11) -> 291.66667 | AG11: =IF(AF11>=$AG$1,"APROVADO","REPROVADO") -> APROVADO
B12: 8 | C12: 008/23 | D12: Organização | E12: Lar Fraterno da Acácia | F12: Aquisição de cadeira de rodas, cadeira de banho, cama, guarda roupa e utensílios para cozinha | G12: Eixo I: Promoção, Assistência e Desenvolvimento Social | H12: 250640 | I12: Jacareí/SP | J12: DRADS VALE DO PARAÍBA EM SÃO JOSÉ DOS CAMPOS | K12: Flávia Aparecida Gonçalves Nascimento | L12: servicosocial.Iarfa@gmail.com | M12: 45296 | N12: Pré-Classificado | O12: Documento Word (Pendrive) | R12: 170 | V12: 302 | W12: 285 | AE12: =COUNT(Q12:AD12) -> 3 | AF12: =AVERAGE(Q12:AD12) -> 252.33333 | AG12: =IF(AF12>=$AG$1,"APROVADO","REPROVADO") -> APROVADO
B13: 9 | C13: 009/23 | D13: Organização | E13: Lar Fraterno da Acácia | F13: Adequação, Acessibilidade | G13: Eixo I: Promoção, Assistência e Desenvolvimento Social | H13: 1288900 | I13: Jacareí/SP | J13: DRADS VALE DO PARAÍBA EM SÃO JOSÉ DOS CAMPOS | K13: Flávia Aparecida Gonçalves Nascimento | L13: servicosocial.Iarfa@gmail.com | M13: 45296 | N13: Pré-Classificado | O13: Documento Word (Pendrive) | R13: 164 | X13: 330 | Y13: 340 | AE13: =COUNT(Q13:AD13) -> 3 | AF13: =AVERAGE(Q13:AD13) -> 278 | AG13: =IF(AF13>=$AG$1,"APROVADO","REPROVADO") -> APROVADO
B14: 10 | C14: 010/23 | D14: Organização | E14: Lar Fraterno da Acácia | F14: Custeio | G14: Eixo I: Promoção, Assistência e Desenvolvimento Social | H14: 1086393.6 | I14: Jacareí/SP | J14: DRADS VALE DO PARAÍBA EM SÃO JOSÉ DOS CAMPOS | K14: Flávia Aparecida Gonçalves Nascimento | L14: z | M14: 45296 | N14: Pré-Classificado | O14: Documento Word (Pendrive) | R14: 146 | V14: 340 | W14: 330 | AE14: =COUNT(Q14:AD14) -> 3 | AF14: =AVERAGE(Q14:AD14) -> 272 | AG14: =IF(AF14>=$AG$1,"APROVADO","REPROVADO") -> APROVADO
B15: 11 | C15: 011/23 | D15: Organização | E15: Obra Social e Assistencial São Lucas | F15: O amor Exige Cuidado | G15: Eixo VII: Cultura, Esporte, Turismo e Lazer | H15: 193281.12 | I15: São José dos Campos/SP | J15: DRADS VALE DO PARAÍBA EM SÃO JOSÉ DOS CAMPOS | K15: Nelcira Rosa da Silva Lima | L15: obrasaolucas@terra.com.br | M15: 45296 | N15: Classificado | Q15: 312 | R15: 199 | S15: 237 | T15: 174 | AE15: =COUNT(Q15:AD15) -> 4 | AF15: =AVERAGE(Q15:AD15) -> 230.5 | AG15: =IF(AF15>=$AG$1,"APROVADO","REPROVADO") -> APROVADO
B16: 12 | C16: 012/23 | D16: Prefeitura | E16: Municipal de Boraceia | F16: Projeto Vida Ativa na Melhor Idade | G16: Eixo I: Promoção, Assistência e Desenvolvimento Social | H16: 244231.32 | I16: Boraceia | J16: DRADS BAURU | K16: Vania de Souza Melo Carlini | L16: orgestorp@hotmail.com | M16: 45296 | N16: Pré-Classificado | O16: Documentos Word (Pendrive) | Q16: 329 | V16: 340 | W16: 323 | AE16: =COUNT(Q16:AD16) -> 3 | AF16: =AVERAGE(Q16:AD16) -> 330.66667 | AG16: =IF(AF16>=$AG$1,"APROVADO","REPROVADO") -> APROVADO
B17: 13 | C17: 013/23 | D17: Organização | E17: Lar dos Velhinhos Papa João XXIII | F17: Cozinha | G17: Eixo I: Promoção, Assistência e Desenvolvimento Social | H17: 69808.08 | I17: Salto Grande/SP | J17: DRADS AVARÉ | K17: Bruna Fernandes Araujo | L17: asilosaltogrande@hotmail.com | M17: 45299 | N17: Classificado | Q17: 329 | R17: 118 | S17: 236 | T17: 200 | AE17: =COUNT(Q17:AD17) -> 4 | AF17: =AVERAGE(Q17:AD17) -> 220.75 | AG17: =IF(AF17>=$AG$1,"APROVADO","REPROVADO") -> APROVADO
B18: 14 | C18: 014/23 | D18: Organização | E18: Lar do Velhinhos Papa João XXIII | F18: Lavanderia | G18: Eixo I: Promoção, Assistência e Desenvolvimento Social | H18: 275400 | I18: Salto Grande/SP | J18: DRADS AVARÉ | K18: Bruna Fernandes Araujo | L18: asiloaltogrande@hotmail.com | M18: 45321 | N18: Classificado | P18: Verificar se não são repetidos (Protocolo 014 e 348/23) | Q18: 288 | R18: 118 | T18: 177 | AF18: =AVERAGE(Q18:AD18) -> 194.33333 | AG18: =IF(AF18>=$AG$1,"APROVADO","REPROVADO") -> REPROVADO
B19: 15 | C19: 015/23 | D19: Organização | E19: Associação Lar dos Idosos de Alvares Machado | F19: EQUIPAR II | G19: Eixo I: Promoção, Assistência e Desenvolvimento Social | H19: 40000 | I19: Álvares Machado/SP | J19: DRADS ALTA SOROCABANA EM PRESIDENTE PRUDENTE | K19: Gislaine Girotti Zanoni | L19: lardosidososdam@yahoo.com.br | M19: 45300 | N19: Classificado | Q19: 340 | R19: 215 | S19: 285 | T19: 300 | AE19: =COUNT(Q19:AD19) -> 4 | AF19: =AVERAGE(Q19:AD19) -> 285 | AG19: =IF(AF19>=$AG$1,"APROVADO","REPROVADO") -> APROVADO
B20: 16 | C20: 016/23 | D20: Organização | E20: ACBNIBRA Associação Cultural, Beneficiente e Esportiva Nipo Brasileiro de Jacupiranga | F20: Projeto Jacupiranga Melhor Idade | G20: Eixo VII: Cultura, Esporte, Turismo e Lazer | H20: 29714 | I20: Jacupiranga/SP | J20: DRADS VALE DO RIBEIRA EM REGISTRO | K20: SR. Angelo | L20: saitto@terra.combr | M20: 45300 | N20: Pré-Classificado | O20: Documento Word (Pendrive) | Q20: 340 | R20: 209 | AD20: 340 | AE20: =COUNT(Q20:AD20) -> 3 | AF20: =AVERAGE(Q20:AD20) -> 296.33333 | AG20: =IF(AF20>=$AG$1,"APROVADO","REPROVADO") -> APROVADO
B21: 17 | C21: 017/23 | D21: Organização | E21: União Espírita Cachoerense | F21: Energia do Bem | G21: Eixo I: Promoção, Assistência e Desenvolvimento Social | H21: 91857.47 | I21: Cachoeira Paulista/SP | J21: DRADS VALE DO PARAÍBA EM SÃO JOSÉ DOS CAMPOS | K21: DéboraFerreira Comonian | L21: u.e.c.1918@gmail.com | M21: 45301 | N21: Classificado | Q21: 340 | R21: 214 | S21: 253 | T21: 242 | AE21: =COUNT(Q21:AD21) -> 4 | AF21: =AVERAGE(Q21:AD21) -> 262.25 | AG21: =IF(AF21>=$AG$1,"APROVADO","REPROVADO") -> APROVADO
B22: 18 | C22: 018/23 | D22: Organização | E22: Obra Unida Lar São Vicente de Paulo de Guariba | F22: Ambiência para o bem-estar e eficiência na aplicação de recursos | G22: Eixo I: Promoção, Assistência e Desenvolvimento Social | H22: 67100 | I22: Guariba/SP | J22: DRADS RIBEIRÃO PRETO | K22: Gabriel Lopes | L22: larsvpguariba@hotmail.com | M22: 45302 | N22: Pré-Classificado | O22: PDF sem rubricas | R22: 199 | X22: 326 | Y22: 323 | AE22: =COUNT(Q22:AD22) -> 3 | AF22: =AVERAGE(Q22:AD22) -> 282.66667 | AG22: =IF(AF22>=$AG$1,"APROVADO","REPROVADO") -> APROVADO
B23: 19 | C23: 019/23 | D23: Prefeitura | E23: Municipal de Pratânia | F23: Grupo Melhor Idade | G23: Eixo I: Promoção, Assistência e Desenvolvimento Social | H23: 120000 | I23: Pratânia/SP | J23: DRADS BOTUCATU | K23: Elaine Cristina Rodrigues Honorato | L23: cras@boraceia.sp.gov.br | M23: 45302 | N23: Classificado | Q23: 297 | S23: 180 | T23: 112 | AF23: =AVERAGE(Q23:AD23) -> 196.33333 | AG23: =IF(AF23>=$AG$1,"APROVADO","REPROVADO") -> REPROVADO
B24: 20 | C24: 020/23 | D24: Prefeitura | E24: Municipal de Regente Feijó | F24: Fomento aos Direitos da Pessoa Idosa de Regente Feijó | G24: Eixo I: Promoção, Assistência e Desenvolvimento Social | H24: 267000 | I24: Regente Feijó | J24: DRADS ALTA SOROCABANA EM PRESIDENTE PRUDENTE | K24: Marcel Henrique de Mello Moraes | L24: asocial1@pratania.sp.gov.br | M24: 45302 | N24: Classificado | Q24: 330 | S24: 160 | T24: 125 | AE24: =COUNT(Q24:AD24) -> 3 | AF24: =AVERAGE(Q24:AD24) -> 205 | AG24: =IF(AF24>=$AG$1,"APROVADO","REPROVADO") -> APROVADO
B25: 21 | C25: 021/23 | D25: Organização | E25: Lar São Vicente de Paulo | F25: Revitalizar Para Melhor Viver | G25: Eixo V: Habitação e Urbanismo | H25: 192880.29 | I25: Santa Cruz do Rio Pardo/SP | J25: DRADS AVARÉ | K25: Acácio Henrique de Lima | L25: s.v.paulo@hotmail.com | M25: 45302 | N25: Desclassificado | O25: Plano de Trabalho sem Rubricar | AF25: =AVERAGE(Q25:AD25) -> #DIV/0! | AG25: =IF(AF25>=$AG$1,"APROVADO","REPROVADO") -> #DIV/0!
B26: 22 | C26: 022/23 | D26: Organização | E26: Lar São Vicente de Paulo | F26: Reforma e Ampliação da Sala de Fisioterapia do Lar São Vicente de Paulo | G26: Eixo I: Promoção, Assistência e Desenvolvimento Social | H26: 50000 | I26: Bernadino de Campo/SP | J26: DRADS BARRETOS | K26: Antônio Roberto de Oliveira | L26: Iarsaovicente@cednet. com. Br | M26: 45302 | N26: Pré-Classificado | O26: Falta de Informação do envelope | P26: Plano e Pendrive OK | Q26: 340 | R26: 178 | AD26: 340 | AE26: =COUNT(Q26:AD26) -> 3 | AF26: =AVERAGE(Q26:AD26) -> 286 | AG26: =IF(AF26>=$AG$1,"APROVADO","REPROVADO") -> APROVADO
B27: 23 | C27: 023/23 | D27: Prefeitura | E27: Municipal de São Jose do Rio Preto | F27: Oficinas e atividades artístico-culturais como instrumento de Intervenção Social Emancipatória para a pessoa idosa em situação de vulnerabilidade social | G27: Eixo VII: Cultura, Esporte, Turismo e Lazer | H27: 414308.85 | I27: São Jose do Rio Preto/SP | J27: DRADS: SÃO JOSÉ DO RIO PRETO | K27: Eliana Cristina Lechado | L27: convenio@regentefeijo.sp.gov.br | M27: 45302 | N27: Classificado | Q27: 297 | R27: 247 | S27: 249 | T27: 246 | AE27: =COUNT(Q27:AD27) -> 4 | AF27: =AVERAGE(Q27:AD27) -> 259.75 | AG27: =IF(AF27>=$AG$1,"APROVADO","REPROVADO") -> APROVADO
B28: 24 | C28: 024/23 | D28: Organização | E28: Abrigo Lar de Jesus | F28: Bem Estar na Melhor Idade de Anhumas | G28: Eixo I: Promoção, Assistência e Desenvolvimento Social | H28: 267766.51 | I28: Anhumas/SP | J28: DRADS ALTA SOROCABANA EM PRESIDENTE PRUDENTE | K28: Robson Mariano | L28: abrigolardejesus@hotmail.com | M28: 45302 | N28: Classificado | Q28: 331 | R28: 139 | S28: 178 | T28: 248 | AE28: =COUNT(Q28:AD28) -> 4 | AF28: =AVERAGE(Q28:AD28) -> 224 | AG28: =IF(AF28>=$AG$1,"APROVADO","REPROVADO") -> APROVADO
B29: 25 | C29: 025/23 | D29: Organização | E29: Associação Congregação de Santa Catarina | F29: Idoso Digital: Inclusão e Fortalecimento da Cidadania para a Pessoa Idosa | G29: Eixo I: Promoção, Assistência e Desenvolvimento Social | H29: 261777 | I29: Guarulhos/SP | J29: DRADS SPN EM GUARULHOS | K29: Mariana S Leonardo | L29: marina.leonardo@redesc.org.br | M29: 45302 | N29: Classificado | Q29: 340 | R29: 256 | S29: 262 | T29: 302 | AE29: =COUNT(Q29:AD29) -> 4 | AF29: =AVERAGE(Q29:AD29) -> 290 | AG29: =IF(AF29>=$AG$1,"APROVADO","REPROVADO") -> APROVADO
B30: 26 | C30: 026/23 | D30: Organização | E30: Associação Congregação de Santa Catarina | F30: Arte em Movimento: A Pessoa Idosa como Consumidora, Produtora e Disseminadora de Cultura | G30: Eixo VII: Cultura, Esporte, Turismo e Lazer | H30: 207810 | I30: Guarulhos/SP | J30: DRADS SPN EM GUARULHOS | K30: Mariana S. Leonardo | L30: mariana.leonardo@redesc.org.br | M30: 45321 | N30: Pré-Classificado | O30: Plano de Trabalho sem n° de páginas | Q30: 340 | R30: 254 | AD30: 340 | AE30: =COUNT(Q30:AD30) -> 3 | AF30: =AVERAGE(Q30:AD30) -> 311.33333 | AG30: =IF(AF30>=$AG$1,"APROVADO","REPROVADO") -> APROVADO
B31: 27 | C31: 027/23 | D31: Organização | E31: Lar São Vicente de Paulo de Taquarituba | F31: Acessibilidade | G31: Eixo V: Habitação e Urbanismo | H31: 150000 | I31: Taquarituba/SP | J31: DRADS AVARÉ | K31: Isabela Steinert Gabriel | L31: larsaovicente-taquarituba@hotmail.com | M31: 45303 | N31: Classificado | Q31: 306 | R31: 55 | T31: 66 | AF31: =AVERAGE(Q31:AD31) -> 142.33333 | AG31: =IF(AF31>=$AG$1,"APROVADO","REPROVADO") -> REPROVADO
B32: 28 | C32: 028/23 | D32: Organização | E32: Lar São Vicente de Paulo de Taquarituba | F32: Garantia de Bem Estar | G32: Eixo I: Promoção, Assistência e Desenvolvimento Social | H32: 120000 | I32: Taquarituba/SP | J32: DRADS AVARÉ | K32: Isabela Steinert Gabriel | L32: larsaovicente-taquarituba@hotmail.com | M32: 45303 | N32: Classificado | Q32: 340 | S32: 60 | T32: 79 | AF32: =AVERAGE(Q32:AD32) -> 159.66667 | AG32: =IF(AF32>=$AG$1,"APROVADO","REPROVADO") -> REPROVADO
B33: 29 | C33: 029/23 | D33: Organização | E33: Lar São Vicente de Paulo de Taquarituba | F33: Higiene Digna | G33: Eixo V: Habitação e Urbanismo | H33: 70000 | I33: Taquarituba/SP | J33: DRADS AVARÉ | K33: Isabela Steinert Gabriel | L33: larsaovicente-taquarituba@hotmail.com | M33: 45303 | N33: Classificado | Q33: 340 | S33: 58 | AB33: 295 | AE33: =COUNT(Q33:AD33) -> 3 | AF33: =AVERAGE(Q33:AD33) -> 231 | AG33: =IF(AF33>=$AG$1,"APROVADO","REPROVADO") -> APROVADO
B34: 30 | C34: 030/23 | D34: Prefeitura | E34: Municipal de Bastos | F34: Idoso em Movimento | G34: Eixo I: Promoção, Assistência e Desenvolvimento Social | H34: 610060.4 | I34: Bastos/SP | J34: DRADS MARÍLIA | K34: Luzia Kiyoko Honda | L34: semas@riopreto.sp.gov.br | M34: 45303 | N34: Reprovado | O34: Aquisição de Veiculo | Q34: 0 | R34: 29 | S34: 44 | AF34: =AVERAGE(Q34:AD34) -> 24.333333 | AG34: =IF(AF34>=$AG$1,"APROVADO","REPROVADO") -> REPROVADO
B35: 31 | C35: 031/23 | D35: Prefeitura | E35: Municipal de Bastos | F35: Longevidade Ativa e Protegida | G35: Eixo I: Promoção, Assistência e Desenvolvimento Social | H35: 160528.4 | I35: Bastos/SP | J35: DRADS MARÍLIA | K35: Luzia Kiyoko Honda | L35: pmbab@Bastos.sp.gov.br | M35: 45303 | N35: Reprovado | O35: Aquisição de Veiculo | Q35: 0 | R35: 169 | S35: 195 | T35: 206 | AF35: =AVERAGE(Q35:AD35) -> 142.5 | AG35: =IF(AF35>=$AG$1,"APROVADO","REPROVADO") -> REPROVADO
B36: 32 | C36: 032/23 | D36: Prefeitura | E36: Municipal São Cetano | F36: Terceira Idade em Movimento | G36: Eixo VII: Cultura, Esporte, Turismo e Lazer | H36: 344990 | I36: São Caetano do Sul/SP | J36: DRADS ABC EM SANTO ANDRÉ | K36: Tatiana | L36: pmbab@Bastos.sp.gov.br | M36: 45303 | N36: Desclassificado | O36: Plano de Trabalho sem Rubricar | AF36: =AVERAGE(Q36:AD36) -> #DIV/0! | AG36: =IF(AF36>=$AG$1,"APROVADO","REPROVADO") -> #DIV/0!
B37: 33 | C37: 033/23 | D37: Organização | E37: Asilo João kuhl Filho | F37: Colorir | G37: Eixo I: Promoção, Assistência e Desenvolvimento Social | H37: 641438.58 | I37: Limeira/SP | J37: DRADS PIRACICABA | K37: Bárbara Letícia Barbosa Pereira | L37: kuhlfilho@yahoo.com | M37: 45303 | N37: Pré-Classificado | R37: 198 | W37: 340 | Y37: 340 | AE37: =COUNT(Q37:AD37) -> 3 | AF37: =AVERAGE(Q37:AD37) -> 292.66667 | AG37: =IF(AF37>=$AG$1,"APROVADO","REPROVADO") -> APROVADO
B38: 34 | C38: 034/23 | D38: Prefeitura | E38: Municipal de Votuporanga | F38: Vida Longa com Automonia e Bem Estar | G38: Eixo I: Promoção, Assistência e Desenvolvimento Social | H38: 100000 | I38: Votuporanga/SP | J38: DRADS FERNANDÓPOLIS | K38: Meire Regina de Azevedo | L38: protecaosocialespecial@votuporanga.sp.gov.br | M38: 45303 | N38: Classificado | Q38: 337 | R38: 184 | S38: 224 | T38: 238 | AE38: =COUNT(Q38:AD38) -> 4 | AF38: =AVERAGE(Q38:AD38) -> 245.75 | AG38: =IF(AF38>=$AG$1,"APROVADO","REPROVADO") -> APROVADO
B39: 35 | C39: 035/23 | D39: Organização | E39: Associação AnhumasQuero-Quero | F39: ConVIVER: Incentivando a Plenitude na 3° Idade | G39: Eixo I: Promoção, Assistência e Desenvolvimento Social | H39: 283010 | I39: Campinas/SP | J39: DRADS CAMPINAS | K39: Felipe Brandão Teles | L39: administrativo@aaqq.org.br | M39: 45303 | N39: Classificado | Q39: 312 | R39: 121 | S39: 222 | T39: 161 | AE39: =COUNT(Q39:AD39) -> 4 | AF39: =AVERAGE(Q39:AD39) -> 204 | AG39: =IF(AF39>=$AG$1,"APROVADO","REPROVADO") -> APROVADO
B40: 36 | C40: 036/23 | D40: Organização | E40: Lar dos Velhinhos Santo Antônio de Juquiá LVSA | F40: Projeto Viver Bem | G40: Eixo I: Promoção, Assistência e Desenvolvimento Social Eixo VII: Cultura, Esporte, Turismo e Lazer | H40: 53388 | I40: Juquia/SP | J40: DRADS VALE DO RIBEIRA EM REGISTRO | K40: Rhiane Mello dos Santos Fernandes | L40: lardosidososdejuquia@gmail.com | M40: 45303 | N40: Classificado | Q40: 297 | AB40: 243 | AC40: 287 | AE40: =COUNT(Q40:AD40) -> 3 | AF40: =AVERAGE(Q40:AD40) -> 275.66667 | AG40: =IF(AF40>=$AG$1,"APROVADO","REPROVADO") -> APROVADO
...

Sheet Consolidada
AG1: 204
B2: CONSELHO ESTADUAL DO IDOSO Rua Boa Vista, 170 - CEP 01204-001 - São Paulo-SP Fone 11-2763-8122/2763-8035 cei@desenvolvimentosocial.sp.gov.br
B3: ORGANIZAÇÕES SOCIAIS
C4: Protocolo | D4: OSC/Prefeitura | E4: NOME DO PROPONENTE | F4: NOME DO PROJETO | G4: EIXO | H4: VALOR TOTAL DO PROJETO | I4: MUNICÍPIO | J4: DRADS | K4: Responsável - OSC | L4: EMAIL | M4: ENTREGUE DIA | N4: ETAPA da Análise | O4: PENDÊNCIA | P4: OBS | Q4: NOTA Gilberto | R4: NOTA Erica | S4: NOTA Enizal | T4: NOTA Walkyria | U4: NOTA Elisete | V4: NOTA Adriano | W4: NOTA Paulo Albano | X4: NOTA Alexandra | Y4: NOTA Priscila | Z4: NOTA Leila | AA4: NOTA Vanise | AB4: NOTA Jeverson | AC4: NOTA Cristiane | AD4: NOTA Márcio | AF4: Média | AG4: RESULTADO FINAL
B5: 1 | C5: 001/23 | D5: Organização | E5: Associação São Joaquim de Apoio à Maturidade | F5: Centro de Convivência Casa Azul | G5: Eixo I: Promoção, Assistência e Desenvolvimento Social | H5: 370460.32 | I5: Carapicuíba/SP | J5: DRADS SPO EM OSASCO | K5: Claudia Regina Ferreira | L5: saojoaquim@saojoaquim.org.br | M5: 45279 | N5: Classificado | Q5: 318 | S5: 265 | T5: 247 | AE5: =COUNT(Q5:AD5) -> 3 | AF5: =AVERAGE(Q5:AD5) -> 276.66667 | AG5: =IF(AF5>=$AG$1,"APROVADO","REPROVADO") -> APROVADO
B6: 2 | C6: 002/23 | D6: Organização | E6: Irmandade Padre Emanoel | F6: CriaMais - Sáude e Arte para Pessoa Idosa | G6: - | H6: 45000 | I6: Palmeira d'Oeste/SP | J6: DRADS FERNANDÓPOLIS | K6: Ludimila Bartolomeu Rodrigues | L6: lardosidosdedalas@hotmail.com | M6: 45313 | N6: Classificado | Q6: 297 | Z6: 310 | AC6: 327 | AE6: =COUNT(Q6:AD6) -> 3 | AF6: =AVERAGE(Q6:AD6) -> 311.33333 | AG6: =IF(AF6>=$AG$1,"APROVADO","REPROVADO") -> APROVADO
B7: 3 | C7: 003/23 | D7: Prefeitura | E7: Municipal de Palmeira D'Oeste | F7: Idoso 100% Ativo – Hidroginastica | G7: Eixo I: Promoção, Assistência e Desenvolvimento Social | H7: 84000 | I7: Palmeira D'Oeste | J7: DRADS FERNANDÓPOLIS | K7: Lucinele Gabaldi Bertolassi | L7: pmpalmeira@ig.com.br | M7: 45282 | N7: Pré-Classificado | O7: Plano de trabalho sem n° de páginas | Q7: 321 | R7: 157 | AB7: 325 | AE7: =COUNT(Q7:AD7) -> 3 | AF7: =AVERAGE(Q7:AD7) -> 267.66667 | AG7: =IF(AF7>=$AG$1,"APROVADO","REPROVADO") -> APROVADO
B8: 4 | C8: 004/23 | D8: Organização | E8: Santa Casa de Misericordia de Presidente Prudente | F8: Tratamento Oftalmológico | G8: Eixo II: Sáude | H8: 1000000 | I8: Presidente Prudente/SP | J8: DRADS ALTA SOROCABANA EM PRESIDENTE PRUDENTE | K8: William Boscoli Ribeiro | L8: analista.adm@santacasaprudente.org.br | M8: 45281 | N8: Pré-Classificado | O8: Plano de Trabalho sem n° de páginas | Q8: 312 | S8: 275 | T8: 299 | AE8: =COUNT(Q8:AD8) -> 3 | AF8: =AVERAGE(Q8:AD8) -> 295.33333 | AG8: =IF(AF8>=$AG$1,"APROVADO","REPROVADO") -> APROVADO
B9: 5 | C9: 005/23 | D9: Organização | E9: Associação Santo Agostinho -ASA | F9: Saber Mais, Viver Mais | G9: Eixo III: Educação | H9: 341605 | I9: São Paulo/SP | J9: DRADS CAPITAL EM SÃO PAULO | K9: Thais Certain | L9: thais.certain@asatransforma.org.br | M9: 45288 | N9: Classificado | Q9: 272 | S9: 269 | T9: 290 | AE9: =COUNT(Q9:AD9) -> 3 | AF9: =AVERAGE(Q9:AD9) -> 277 | AG9: =IF(AF9>=$AG$1,"APROVADO","REPROVADO") -> APROVADO
B10: 6 | C10: 006/23 | D10: Organização | E10: Congregação Israelita Paulista | F10: Núcleo de Convivência da Maturidade | G10: Eixo I: Promoção, Assistência e Desenvolvimento Social | H10: 523070 | I10: São Paulo/SP | J10: DRADS CAPITAL EM SÃO PAULO | K10: Laura Feldman | L10: acaosocial@cip.org.br | M10: 45288 | N10: Desclassificado | O10: Plano de Trabalho sem Rubricar | AF10: =AVERAGE(Q10:AD10) -> #DIV/0! | AG10: =IF(AF10>=$AG$1,"APROVADO","REPROVADO") -> #DIV/0!
B11: 7 | C11: 007/23 | D11: Organização | E11: Associação de Apoio ao Paciente Renal Cronico e Transplantado -Carim | F11: Saúde e Movimento | G11: - | H11: 364980 | I11: Presidente Prudente/SP | J11: DRADS ALTA SOROCABANA EM PRESIDENTE PRUDENTE | K11: Sumaia Cristina Zahra Zakir Pereira | L11: carimprudente@yahoo.com. br | M11: 45289 | N11: Pré-Classificado | O11: Falta de Informação do envelope | P11: Doc Word | Q11: 340 | S11: 245 | T11: 290 | AE11: =COUNT(Q11:AD11) -> 3 | AF11: =AVERAGE(Q11:AD11) -> 291.66667 | AG11: =IF(AF11>=$AG$1,"APROVADO","REPROVADO") -> APROVADO
B12: 8 | C12: 008/23 | D12: Organização | E12: Lar Fraterno da Acácia | F12: Aquisição de cadeira de rodas, cadeira de banho, cama, guarda roupa e utensílios para cozinha | G12: Eixo I: Promoção, Assistência e Desenvolvimento Social | H12: 250640 | I12: Jacareí/SP | J12: DRADS VALE DO PARAÍBA EM SÃO JOSÉ DOS CAMPOS | K12: Flávia Aparecida Gonçalves Nascimento | L12: servicosocial.Iarfa@gmail.com | M12: 45296 | N12: Pré-Classificado | O12: Documento Word (Pendrive) | R12: 170 | V12: 302 | W12: 285 | AE12: =COUNT(Q12:AD12) -> 3 | AF12: =AVERAGE(Q12:AD12) -> 252.33333 | AG12: =IF(AF12>=$AG$1,"APROVADO","REPROVADO") -> APROVADO
B13: 9 | C13: 009/23 | D13: Organização | E13: Lar Fraterno da Acácia | F13: Adequação, Acessibilidade | G13: Eixo I: Promoção, Assistência e Desenvolvimento Social | H13: 1288900 | I13: Jacareí/SP | J13: DRADS VALE DO PARAÍBA EM SÃO JOSÉ DOS CAMPOS | K13: Flávia Aparecida Gonçalves Nascimento | L13: servicosocial.Iarfa@gmail.com | M13: 45296 | N13: Pré-Classificado | O13: Documento Word (Pendrive) | R13: 164 | X13: 330 | Y13: 340 | AE13: =COUNT(Q13:AD13) -> 3 | AF13: =AVERAGE(Q13:AD13) -> 278 | AG13: =IF(AF13>=$AG$1,"APROVADO","REPROVADO") -> APROVADO
B14: 10 | C14: 010/23 | D14: Organização | E14: Lar Fraterno da Acácia | F14: Custeio | G14: Eixo I: Promoção, Assistência e Desenvolvimento Social | H14: 1086393.6 | I14: Jacareí/SP | J14: DRADS VALE DO PARAÍBA EM SÃO JOSÉ DOS CAMPOS | K14: Flávia Aparecida Gonçalves Nascimento | L14: z | M14: 45296 | N14: Pré-Classificado | O14: Documento Word (Pendrive) | R14: 146 | V14: 340 | W14: 330 | AE14: =COUNT(Q14:AD14) -> 3 | AF14: =AVERAGE(Q14:AD14) -> 272 | AG14: =IF(AF14>=$AG$1,"APROVADO","REPROVADO") -> APROVADO
B15: 11 | C15: 011/23 | D15: Organização | E15: Obra Social e Assistencial São Lucas | F15: O amor Exige Cuidado | G15: Eixo VII: Cultura, Esporte, Turismo e Lazer | H15: 193281.12 | I15: São José dos Campos/SP | J15: DRADS VALE DO PARAÍBA EM SÃO JOSÉ DOS CAMPOS | K15: Nelcira Rosa da Silva Lima | L15: obrasaolucas@terra.com.br | M15: 45296 | N15: Classificado | Q15: 312 | S15: 237 | T15: 174 | AE15: =COUNT(Q15:AD15) -> 3 | AF15: =AVERAGE(Q15:AD15) -> 241 | AG15: =IF(AF15>=$AG$1,"APROVADO","REPROVADO") -> APROVADO
B16: 12 | C16: 012/23 | D16: Prefeitura | E16: Municipal de Boraceia | F16: Projeto Vida Ativa na Melhor Idade | G16: Eixo I: Promoção, Assistência e Desenvolvimento Social | H16: 244231.32 | I16: Boraceia | J16: DRADS BAURU | K16: Vania de Souza Melo Carlini | L16: orgestorp@hotmail.com | M16: 45296 | N16: Pré-Classificado | O16: Documentos Word (Pendrive) | Q16: 329 | V16: 340 | W16: 323 | AE16: =COUNT(Q16:AD16) -> 3 | AF16: =AVERAGE(Q16:AD16) -> 330.66667 | AG16: =IF(AF16>=$AG$1,"APROVADO","REPROVADO") -> APROVADO
B17: 13 | C17: 013/23 | D17: Organização | E17: Lar dos Velhinhos Papa João XXIII | F17: Cozinha | G17: Eixo I: Promoção, Assistência e Desenvolvimento Social | H17: 69808.08 | I17: Salto Grande/SP | J17: DRADS AVARÉ | K17: Bruna Fernandes Araujo | L17: asilosaltogrande@hotmail.com | M17: 45299 | N17: Classificado | Q17: 329 | S17: 236 | T17: 200 | AE17: =COUNT(Q17:AD17) -> 3 | AF17: =AVERAGE(Q17:AD17) -> 255 | AG17: =IF(AF17>=$AG$1,"APROVADO","REPROVADO") -> APROVADO
B18: 14 | C18: 014/23 | D18: Organização | E18: Lar do Velhinhos Papa João XXIII | F18: Lavanderia | G18: Eixo I: Promoção, Assistência e Desenvolvimento Social | H18: 275400 | I18: Salto Grande/SP | J18: DRADS AVARÉ | K18: Bruna Fernandes Araujo | L18: asiloaltogrande@hotmail.com | M18: 45321 | N18: Classificado | P18: Verificar se não são repetidos (Protocolo 014 e 348/23) | Q18: 288 | R18: 118 | T18: 177 | AE18: =COUNT(Q18:AD18) -> 3 | AF18: =AVERAGE(Q18:AD18) -> 194.33333 | AG18: =IF(AF18>=$AG$1,"APROVADO","REPROVADO") -> REPROVADO
B19: 15 | C19: 015/23 | D19: Organização | E19: Associação Lar dos Idosos de Alvares Machado | F19: EQUIPAR II | G19: Eixo I: Promoção, Assistência e Desenvolvimento Social | H19: 40000 | I19: Álvares Machado/SP | J19: DRADS ALTA SOROCABANA EM PRESIDENTE PRUDENTE | K19: Gislaine Girotti Zanoni | L19: lardosidososdam@yahoo.com.br | M19: 45300 | N19: Classificado | Q19: 340 | S19: 285 | T19: 300 | AE19: =COUNT(Q19:AD19) -> 3 | AF19: =AVERAGE(Q19:AD19) -> 308.33333 | AG19: =IF(AF19>=$AG$1,"APROVADO","REPROVADO") -> APROVADO
B20: 16 | C20: 016/23 | D20: Organização | E20: ACBNIBRA Associação Cultural, Beneficiente e Esportiva Nipo Brasileiro de Jacupiranga | F20: Projeto Jacupiranga Melhor Idade | G20: Eixo VII: Cultura, Esporte, Turismo e Lazer | H20: 29714 | I20: Jacupiranga/SP | J20: DRADS VALE DO RIBEIRA EM REGISTRO | K20: SR. Angelo | L20: saitto@terra.combr | M20: 45300 | N20: Pré-Classificado | O20: Documento Word (Pendrive) | Q20: 340 | R20: 209 | AD20: 340 | AE20: =COUNT(Q20:AD20) -> 3 | AF20: =AVERAGE(Q20:AD20) -> 296.33333 | AG20: =IF(AF20>=$AG$1,"APROVADO","REPROVADO") -> APROVADO
B21: 17 | C21: 017/23 | D21: Organização | E21: União Espírita Cachoerense | F21: Energia do Bem | G21: Eixo I: Promoção, Assistência e Desenvolvimento Social | H21: 91857.47 | I21: Cachoeira Paulista/SP | J21: DRADS VALE DO PARAÍBA EM SÃO JOSÉ DOS CAMPOS | K21: DéboraFerreira Comonian | L21: u.e.c.1918@gmail.com | M21: 45301 | N21: Classificado | Q21: 340 | S21: 253 | T21: 242 | AE21: =COUNT(Q21:AD21) -> 3 | AF21: =AVERAGE(Q21:AD21) -> 278.33333 | AG21: =IF(AF21>=$AG$1,"APROVADO","REPROVADO") -> APROVADO
B22: 18 | C22: 018/23 | D22: Organização | E22: Obra Unida Lar São Vicente de Paulo de Guariba | F22: Ambiência para o bem-estar e eficiência na aplicação de recursos | G22: Eixo I: Promoção, Assistência e Desenvolvimento Social | H22: 67100 | I22: Guariba/SP | J22: DRADS RIBEIRÃO PRETO | K22: Gabriel Lopes | L22: larsvpguariba@hotmail.com | M22: 45302 | N22: Pré-Classificado | O22: PDF sem rubricas | R22: 199 | X22: 326 | Y22: 323 | AE22: =COUNT(Q22:AD22) -> 3 | AF22: =AVERAGE(Q22:AD22) -> 282.66667 | AG22: =IF(AF22>=$AG$1,"APROVADO","REPROVADO") -> APROVADO
B23: 19 | C23: 019/23 | D23: Prefeitura | E23: Municipal de Pratânia | F23: Grupo Melhor Idade | G23: Eixo I: Promoção, Assistência e Desenvolvimento Social | H23: 120000 | I23: Pratânia/SP | J23: DRADS BOTUCATU | K23: Elaine Cristina Rodrigues Honorato | L23: cras@boraceia.sp.gov.br | M23: 45302 | N23: Classificado | Q23: 297 | S23: 180 | T23: 112 | AE23: =COUNT(Q23:AD23) -> 3 | AF23: =AVERAGE(Q23:AD23) -> 196.33333 | AG23: =IF(AF23>=$AG$1,"APROVADO","REPROVADO") -> REPROVADO
B24: 20 | C24: 020/23 | D24: Prefeitura | E24: Municipal de Regente Feijó | F24: Fomento aos Direitos da Pessoa Idosa de Regente Feijó | G24: Eixo I: Promoção, Assistência e Desenvolvimento Social | H24: 267000 | I24: Regente Feijó | J24: DRADS ALTA SOROCABANA EM PRESIDENTE PRUDENTE | K24: Marcel Henrique de Mello Moraes | L24: asocial1@pratania.sp.gov.br | M24: 45302 | N24: Classificado | Q24: 330 | S24: 160 | T24: 125 | AE24: =COUNT(Q24:AD24) -> 3 | AF24: =AVERAGE(Q24:AD24) -> 205 | AG24: =IF(AF24>=$AG$1,"APROVADO","REPROVADO") -> APROVADO
B25: 21 | C25: 021/23 | D25: Organização | E25: Lar São Vicente de Paulo | F25: Revitalizar Para Melhor Viver | G25: Eixo V: Habitação e Urbanismo | H25: 192880.29 | I25: Santa Cruz do Rio Pardo/SP | J25: DRADS AVARÉ | K25: Acácio Henrique de Lima | L25: s.v.paulo@hotmail.com | M25: 45302 | N25: Desclassificado | O25: Plano de Trabalho sem Rubricar | AF25: =AVERAGE(Q25:AD25) -> #DIV/0! | AG25: =IF(AF25>=$AG$1,"APROVADO","REPROVADO") -> #DIV/0!
B26: 22 | C26: 022/23 | D26: Organização | E26: Lar São Vicente de Paulo | F26: Reforma e Ampliação da Sala de Fisioterapia do Lar São Vicente de Paulo | G26: Eixo I: Promoção, Assistência e Desenvolvimento Social | H26: 50000 | I26: Bernadino de Campo/SP | J26: DRADS BARRETOS | K26: Antônio Roberto de Oliveira | L26: Iarsaovicente@cednet. com. Br | M26: 45302 | N26: Pré-Classificado | O26: Falta de Informação do envelope | P26: Plano e Pendrive OK | Q26: 340 | R26: 178 | AD26: 340 | AE26: =COUNT(Q26:AD26) -> 3 | AF26: =AVERAGE(Q26:AD26) -> 286 | AG26: =IF(AF26>=$AG$1,"APROVADO","REPROVADO") -> APROVADO
B27: 23 | C27: 023/23 | D27: Prefeitura | E27: Municipal de São Jose do Rio Preto | F27: Oficinas e atividades artístico-culturais como instrumento de Intervenção Social Emancipatória para a pessoa idosa em situação de vulnerabilidade social | G27: Eixo VII: Cultura, Esporte, Turismo e Lazer | H27: 414308.85 | I27: São Jose do Rio Preto/SP | J27: DRADS: SÃO JOSÉ DO RIO PRETO | K27: Eliana Cristina Lechado | L27: convenio@regentefeijo.sp.gov.br | M27: 45302 | N27: Classificado | Q27: 297 | R27: 247 | S27: 249 | AE27: =COUNT(Q27:AD27) -> 3 | AF27: =AVERAGE(Q27:AD27) -> 264.33333 | AG27: =IF(AF27>=$AG$1,"APROVADO","REPROVADO") -> APROVADO
B28: 24 | C28: 024/23 | D28: Organização | E28: Abrigo Lar de Jesus | F28: Bem Estar na Melhor Idade de Anhumas | G28: Eixo I: Promoção, Assistência e Desenvolvimento Social | H28: 267766.51 | I28: Anhumas/SP | J28: DRADS ALTA SOROCABANA EM PRESIDENTE PRUDENTE | K28: Robson Mariano | L28: abrigolardejesus@hotmail.com | M28: 45302 | N28: Classificado | Q28: 331 | S28: 178 | T28: 248 | AE28: =COUNT(Q28:AD28) -> 3 | AF28: =AVERAGE(Q28:AD28) -> 252.33333 | AG28: =IF(AF28>=$AG$1,"APROVADO","REPROVADO") -> APROVADO
B29: 25 | C29: 025/23 | D29: Organização | E29: Associação Congregação de Santa Catarina | F29: Idoso Digital: Inclusão e Fortalecimento da Cidadania para a Pessoa Idosa | G29: Eixo I: Promoção, Assistência e Desenvolvimento Social | H29: 261777 | I29: Guarulhos/SP | J29: DRADS SPN EM GUARULHOS | K29: Mariana S Leonardo | L29: marina.leonardo@redesc.org.br | M29: 45302 | N29: Classificado | Q29: 340 | S29: 262 | T29: 302 | AE29: =COUNT(Q29:AD29) -> 3 | AF29: =AVERAGE(Q29:AD29) -> 301.33333 | AG29: =IF(AF29>=$AG$1,"APROVADO","REPROVADO") -> APROVADO
B30: 26 | C30: 026/23 | D30: Organização | E30: Associação Congregação de Santa Catarina | F30: Arte em Movimento: A Pessoa Idosa como Consumidora, Produtora e Disseminadora de Cultura | G30: Eixo VII: Cultura, Esporte, Turismo e Lazer | H30: 207810 | I30: Guarulhos/SP | J30: DRADS SPN EM GUARULHOS | K30: Mariana S. Leonardo | L30: mariana.leonardo@redesc.org.br | M30: 45321 | N30: Pré-Classificado | O30: Plano de Trabalho sem n° de páginas | Q30: 340 | R30: 254 | AD30: 340 | AE30: =COUNT(Q30:AD30) -> 3 | AF30: =AVERAGE(Q30:AD30) -> 311.33333 | AG30: =IF(AF30>=$AG$1,"APROVADO","REPROVADO") -> APROVADO
B31: 27 | C31: 027/23 | D31: Organização | E31: Lar São Vicente de Paulo de Taquarituba | F31: Acessibilidade | G31: Eixo V: Habitação e Urbanismo | H31: 150000 | I31: Taquarituba/SP | J31: DRADS AVARÉ | K31: Isabela Steinert Gabriel | L31: larsaovicente-taquarituba@hotmail.com | M31: 45303 | N31: Classificado | Q31: 306 | R31: 55 | T31: 66 | AE31: =COUNT(Q31:AD31) -> 3 | AF31: =AVERAGE(Q31:AD31) -> 142.33333 | AG31: =IF(AF31>=$AG$1,"APROVADO","REPROVADO") -> REPROVADO
B32: 28 | C32: 028/23 | D32: Organização | E32: Lar São Vicente de Paulo de Taquarituba | F32: Garantia de Bem Estar | G32: Eixo I: Promoção, Assistência e Desenvolvimento Social | H32: 120000 | I32: Taquarituba/SP | J32: DRADS AVARÉ | K32: Isabela Steinert Gabriel | L32: larsaovicente-taquarituba@hotmail.com | M32: 45303 | N32: Classificado | Q32: 340 | S32: 60 | T32: 79 | AE32: =COUNT(Q32:AD32) -> 3 | AF32: =AVERAGE(Q32:AD32) -> 159.66667 | AG32: =IF(AF32>=$AG$1,"APROVADO","REPROVADO") -> REPROVADO
B33: 29 | C33: 029/23 | D33: Organização | E33: Lar São Vicente de Paulo de Taquarituba | F33: Higiene Digna | G33: Eixo V: Habitação e Urbanismo | H33: 70000 | I33: Taquarituba/SP | J33: DRADS AVARÉ | K33: Isabela Steinert Gabriel | L33: larsaovicente-taquarituba@hotmail.com | M33: 45303 | N33: Classificado | Q33: 340 | S33: 58 | AB33: 295 | AE33: =COUNT(Q33:AD33) -> 3 | AF33: =AVERAGE(Q33:AD33) -> 231 | AG33: =IF(AF33>=$AG$1,"APROVADO","REPROVADO") -> APROVADO
B34: 30 | C34: 030/23 | D34: Prefeitura | E34: Municipal de Bastos | F34: Idoso em Movimento | G34: Eixo I: Promoção, Assistência e Desenvolvimento Social | H34: 610060.4 | I34: Bastos/SP | J34: DRADS MARÍLIA | K34: Luzia Kiyoko Honda | L34: semas@riopreto.sp.gov.br | M34: 45303 | N34: Reprovado | O34: Aquisição de Veiculo | Q34: 0 | R34: 29 | S34: 44 | AF34: =AVERAGE(Q34:AD34) -> 24.333333 | AG34: =IF(AF34>=$AG$1,"APROVADO","REPROVADO") -> REPROVADO
B35: 31 | C35: 031/23 | D35: Prefeitura | E35: Municipal de Bastos | F35: Longevidade Ativa e Protegida | G35: Eixo I: Promoção, Assistência e Desenvolvimento Social | H35: 160528.4 | I35: Bastos/SP | J35: DRADS MARÍLIA | K35: Luzia Kiyoko Honda | L35: pmbab@Bastos.sp.gov.br | M35: 45303 | N35: Reprovado | O35: Aquisição de Veiculo | Q35: 0 | R35: 169 | S35: 195 | T35: 206 | AF35: =AVERAGE(Q35:AD35) -> 142.5 | AG35: =IF(AF35>=$AG$1,"APROVADO","REPROVADO") -> REPROVADO
B36: 32 | C36: 032/23 | D36: Prefeitura | E36: Municipal São Cetano | F36: Terceira Idade em Movimento | G36: Eixo VII: Cultura, Esporte, Turismo e Lazer | H36: 344990 | I36: São Caetano do Sul/SP | J36: DRADS ABC EM SANTO ANDRÉ | K36: Tatiana | L36: pmbab@Bastos.sp.gov.br | M36: 45303 | N36: Desclassificado | O36: Plano de Trabalho sem Rubricar | AF36: =AVERAGE(Q36:AD36) -> #DIV/0! | AG36: =IF(AF36>=$AG$1,"APROVADO","REPROVADO") -> #DIV/0!
B37: 33 | C37: 033/23 | D37: Organização | E37: Asilo João kuhl Filho | F37: Colorir | G37: Eixo I: Promoção, Assistência e Desenvolvimento Social | H37: 641438.58 | I37: Limeira/SP | J37: DRADS PIRACICABA | K37: Bárbara Letícia Barbosa Pereira | L37: kuhlfilho@yahoo.com | M37: 45303 | N37: Pré-Classificado | R37: 198 | W37: 340 | Y37: 340 | AE37: =COUNT(Q37:AD37) -> 3 | AF37: =AVERAGE(Q37:AD37) -> 292.66667 | AG37: =IF(AF37>=$AG$1,"APROVADO","REPROVADO") -> APROVADO
B38: 34 | C38: 034/23 | D38: Prefeitura | E38: Municipal de Votuporanga | F38: Vida Longa com Automonia e Bem Estar | G38: Eixo I: Promoção, Assistência e Desenvolvimento Social | H38: 100000 | I38: Votuporanga/SP | J38: DRADS FERNANDÓPOLIS | K38: Meire Regina de Azevedo | L38: protecaosocialespecial@votuporanga.sp.gov.br | M38: 45303 | N38: Classificado | Q38: 337 | S38: 224 | T38: 238 | AE38: =COUNT(Q38:AD38) -> 3 | AF38: =AVERAGE(Q38:AD38) -> 266.33333 | AG38: =IF(AF38>=$AG$1,"APROVADO","REPROVADO") -> APROVADO
B39: 35 | C39: 035/23 | D39: Organização | E39: Associação AnhumasQuero-Quero | F39: ConVIVER: Incentivando a Plenitude na 3° Idade | G39: Eixo I: Promoção, Assistência e Desenvolvimento Social | H39: 283010 | I39: Campinas/SP | J39: DRADS CAMPINAS | K39: Felipe Brandão Teles | L39: administrativo@aaqq.org.br | M39: 45303 | N39: Classificado | Q39: 312 | S39: 222 | T39: 161 | AE39: =COUNT(Q39:AD39) -> 3 | AF39: =AVERAGE(Q39:AD39) -> 231.66667 | AG39: =IF(AF39>=$AG$1,"APROVADO","REPROVADO") -> APROVADO
B40: 36 | C40: 036/23 | D40: Organização | E40: Lar dos Velhinhos Santo Antônio de Juquiá LVSA | F40: Projeto Viver Bem | G40: Eixo I: Promoção, Assistência e Desenvolvimento Social Eixo VII: Cultura, Esporte, Turismo e Lazer | H40: 53388 | I40: Juquia/SP | J40: DRADS VALE DO RIBEIRA EM REGISTRO | K40: Rhiane Mello dos Santos Fernandes | L40: lardosidososdejuquia@gmail.com | M40: 45303 | N40: Classificado | Q40: 297 | AB40: 243 | AC40: 287 | AE40: =COUNT(Q40:AD40) -> 3 | AF40: =AVERAGE(Q40:AD40) -> 275.66667 | AG40: =IF(AF40>=$AG$1,"APROVADO","REPROVADO") -> APROVADO
...

Sheet Desclassificado
AF1: 204
B2: CONSELHO ESTADUAL DO IDOSO Rua Boa Vista, 170- CEP 01204-001 - São Paulo-SP Fone 11-2763-8122/2763-8035 cei@desenvolvimentosocial.sp.gov.br
B3: ORGANIZAÇÕES SOCIAIS
C4: Protocolo | D4: OSC/Prefeitura | E4: NOME DO PROPONENTE | F4: NOME DO PROJETO | G4: EIXO | H4: VALOR TOTAL DO PROJETO | I4: MUNICÍPIO | J4: DRADS | K4: Responsável - OSC | L4: EMAIL | M4: ENTREGUE DIA | N4: ETAPA da Análise | O4: PENDÊNCIA | P4: OBS | Q4: NOTA Gilberto | R4: NOTA Erica | S4: NOTA Enizal | T4: NOTA Walkyria | U4: NOTA Elisete | V4: NOTA Adriano | W4: NOTA Paulo Albano | X4: NOTA Alexandra | Y4: NOTA Priscila | Z4: NOTA Leila | AA4: NOTA Vanise | AB4: NOTA Jeverson | AC4: NOTA Cristiane | AD4: NOTA Márcio | AE4: Média | AF4: RESULTADO FINAL
B5: 6 | C5: 006/23 | D5: Organização | E5: Congregação Israelita Paulista | F5: Núcleo de Convivência da Maturidade | G5: Eixo I: Promoção, Assistência e Desenvolvimento Social | H5: 523070 | I5: São Paulo/SP | J5: DRADS CAPITAL EM SÃO PAULO | K5: Laura Feldman | L5: acaosocial@cip.org.br | M5: 45288 | N5: Desclassificado | O5: Plano de Trabalho não está Rubricado | AE5: =AVERAGE(Q5:AD5) -> #DIV/0! | AF5: =IF(AE5>=$AF$1,"APROVADO","REPROVADO") -> #DIV/0!
B6: 21 | C6: 021/23 | D6: Organização | E6: Lar São Vicente de Paulo | F6: Revitalizar Para Melhor Viver | G6: Eixo V: Habitação e Urbanismo | H6: 192880.29 | I6: Santa Cruz do Rio Pardo/SP | J6: DRADS AVARÉ | K6: Acácio Henrique de Lima | L6: s.v.paulo@hotmail.com | M6: 45302 | N6: Desclassificado | O6: Plano de Trabalho não está Rubricado | AE6: =AVERAGE(Q6:AD6) -> #DIV/0! | AF6: =IF(AE6>=$AF$1,"APROVADO","REPROVADO") -> #DIV/0!
B7: 32 | C7: 032/23 | D7: Prefeitura | E7: Municipal São Cetano | F7: Terceira Idade em Movimento | G7: Eixo VII: Cultura, Esporte, Turismo e Lazer | H7: 344990 | I7: São Caetano do Sul/SP | J7: DRADS ABC EM SANTO ANDRÉ | K7: Tatiana | L7: pmbab@Bastos.sp.gov.br | M7: 45303 | N7: Desclassificado | O7: Plano de Trabalho não está Rubricado | AE7: =AVERAGE(Q7:AD7) -> #DIV/0! | AF7: =IF(AE7>=$AF$1,"APROVADO","REPROVADO") -> #DIV/0!
B8: 70 | C8: 070/23 | D8: Organização | E8: Lar dos Velhinhos São Vicente de Paulo | F8: Idoso Jovem | G8: Eixo I: Promoção, Assistência e Desenvolvimento Social | H8: 38337 | I8: Urânia/SP | J8: DRADS FERNANDÓPOLIS | K8: Zélia Souza Silva | L8: lardos velhinhos1@hotmail.com | M8: 45306 | N8: Desclassificado | O8: Sem Pendrive | AE8: =AVERAGE(Q8:AD8) -> #DIV/0! | AF8: =IF(AE8>=$AF$1,"APROVADO","REPROVADO") -> #DIV/0!
B9: 71 | C9: 071/23 | D9: Organização | E9: Lar dos Velhinhos São Vicente de Paulo | F9: Meu Quarto Meus Sonhos | G9: Eixo I: Promoção, Assistência e Desenvolvimento Social | H9: 78212 | I9: Urânia/SP | J9: DRADS FERNANDÓPOLIS | K9: Zélia Souza Silva | L9: lardos velhinhos1@hotmail.com | M9: 45306 | N9: Desclassificado | O9: Sem Pendrive | AE9: =AVERAGE(Q9:AD9) -> #DIV/0! | AF9: =IF(AE9>=$AF$1,"APROVADO","REPROVADO") -> #DIV/0!
B10: 82 | C10: 082/23 | D10: Organização | E10: Vila Vicentina em Brotas | F10: Bem Estar Social aos Idosos (mesas e Cadeiras) | G10: Eixo I: Promoção, Assistência e Desenvolvimento Social | H10: 10000 | I10: Brotas/SP | J10: DRADS PIRACICABA | K10: Neuza Maria Pascoalotti Berto | L10: vilavicentinoembrotas@outlook.com | M10: 45307 | N10: Desclassificado | O10: Sem Pendrive | AE10: =AVERAGE(Q10:AD10) -> #DIV/0! | AF10: =IF(AE10>=$AF$1,"APROVADO","REPROVADO") -> #DIV/0!
B11: 83 | C11: 083/23 | D11: Organização | E11: Vila Vicentina em Brotas | F11: Aconchego aos Idosos (Poltrona do Papai Reclinável) | G11: Eixo I: Promoção, Assistência e Desenvolvimento Social | H11: 10000 | I11: Brotas/SP | J11: DRADS PIRACICABA | K11: Neuza Maria Pascoalotti Berto | L11: vilavicentinoembrotas@outlook.com | M11: 45307 | N11: Desclassificado | O11: Sem Pendrive | AE11: =AVERAGE(Q11:AD11) -> #DIV/0! | AF11: =IF(AE11>=$AF$1,"APROVADO","REPROVADO") -> #DIV/0!
B12: 90 | C12: 090/23 | D12: Organização | E12: Associação Cultural e Social do Idoso Criança e Adolescente | F12: Exposição do Samba - Velha Guarda | G12: Eixo VII: Cultura, Esporte, Turismo e Lazer | H12: 630000 | I12: São Paulo/SP | J12: DRADS CAPITAL EM SÃO PAULO | K12: Emerson de Godoy Costas dos Santos | L12: coordenacaoacsica@hotmail.com | M12: 45307 | N12: Desclassificado | O12: Plano de Trabalho não está Rubricado | AE12: =AVERAGE(Q12:AD12) -> #DIV/0! | AF12: =IF(AE12>=$AF$1,"APROVADO","REPROVADO") -> #DIV/0!
B13: 91 | C13: 091/23 | D13: Organização | E13: Associação Beneficiente Bom Jesus | F13: Viver Bem | G13: Eixo VII: Cultura, Esporte, Turismo e Lazer | H13: 50000 | I13: Pilar do Sul/SP | J13: DRADS SOROCABA | K13: Sergio Luis Ribeiro | L13: larbomjesus.pilardosul@gmail.com | M13: 45307 | N13: Desclassificado | O13: Plano de Trabalho não está Rubricado | AE13: =AVERAGE(Q13:AD13) -> #DIV/0! | AF13: =IF(AE13>=$AF$1,"APROVADO","REPROVADO") -> #DIV/0!
B14: 102 | C14: 102/23 | D14: Organização | E14: Vila Vicentina AraraquaraObra Unida á Sociedade de São Vicente de Paulo | F14: Alimentação Fundamental | G14: Eixo I: Promoção, Assistência e Desenvolvimento Social | H14: 120000 | I14: Araraquara/SP | J14: DRADS ARARAQUARA | K14: Nathan Reinaldo Carvalho Silva | L14: servicosocial@vilavicentinaararaquara.org.br | M14: 45307 | N14: Desclassificado | O14: Sem Pendrive | AE14: =AVERAGE(Q14:AD14) -> #DIV/0! | AF14: =IF(AE14>=$AF$1,"APROVADO","REPROVADO") -> #DIV/0!
B15: 123 | C15: 123/23 | D15: Organização | E15: Associação União Beneficiente das Irmãs de São Vicente de Paulo de Gysegem | F15: Projeto Bem Estar das Instalações da Pessoa Idosa em ILPI | G15: Eixo I: Promoção, Assistência e Desenvolvimento Social | H15: 2241683 | I15: Jundiaí/SP | J15: DRADS CAMPINAS | K15: Neide Calandrin | L15: ssocial.lar@vicentinas.com.br | M15: 45308 | N15: Desclassificado | O15: Sem Pendrive | AE15: =AVERAGE(Q15:AD15) -> #DIV/0! | AF15: =IF(AE15>=$AF$1,"APROVADO","REPROVADO") -> #DIV/0!
B16: 124 | C16: 124/23 | D16: Organização | E16: Instituto Reviver de Biritiba Mirim | F16: Vida Ativa com Saúde | G16: Eixo I: Promoção, Assistência e Desenvolvimento Social | H16: 373709.52 | I16: Biritiba Mirim/SP | J16: DRADS SPL EM MOGI DAS CRUZES | K16: Beatriz | L16: reviverbm@gmail.com | M16: 45308 | N16: Desclassificado | O16: Plano de Trabalho não está Rubricado | AE16: =AVERAGE(Q16:AD16) -> #DIV/0! | AF16: =IF(AE16>=$AF$1,"APROVADO","REPROVADO") -> #DIV/0!
... B67: 543 | C67: 543/23 | D67: Organização | E67: Cáritas Paroquial Nossa Mãe dos Homens e Santo Antônio de Pádua | F67: Ser Pleno | G67: Eixo I: Promoção, Assistência e Desenvolvimento Social | H67: 500000 | I67: Louveira/SP | J67: DRADS CAMPINAS | K67: Fabiana Cristina | L67: coordenacaocaritasparoquial@gmail.com | M67: 45322 | N67: Desclassificado | O67: Plano de Trabalho não está Rubricado | AE67: =AVERAGE(Q67:AD67) -> #DIV/0! | AF67: =IF(AE67>=$AF$1,"APROVADO","REPROVADO") -> #DIV/0!
B68: 559 | C68: 559/23 | D68: Organização | E68: Coordenação Regional das Obras de Promoção Humanas - CROPH | F68: - | G68: - | H68: 0 | I68: São Paulo/SP | J68: DRADS CAPITAL EM SÃO PAULO | K68: Carlota Cardoso da Silva | L68: contato@croph.org.br | M68: 45322 | N68: Desclassificado | O68: Plano de Trabalho não está Rubricado | P68: Sem Pendrive e faltando várias informaçãoes no Plano de Trabalho | AE68: =AVERAGE(Q68:AD68) -> #DIV/0! | AF68: =IF(AE68>=$AF$1,"APROVADO","REPROVADO") -> #DIV/0!
B69: 560 | C69: 560/23 | D69: Organização | E69: Associação Cuidado ao Próximo | F69: - | G69: - | H69: - | I69: São Paulo/SP | J69: DRADS CAPITAL EM SÃO PAULO | K69: Marcos Antônio Bamban Pereira | L69: cuidadoaoproximo@gmail.com | M69: 45322 | N69: Desclassificado | O69: Plano de Trabalho não está Rubricado | AE69: =AVERAGE(Q69:AD69) -> #DIV/0! | AF69: =IF(AE69>=$AF$1,"APROVADO","REPROVADO") -> #DIV/0!
B70: 573 | C70: 571/23 | D70: Organização | E70: Instituto Futuro | F70: Cultura e Ação | G70: Eixo VII: Cultura, Esporte, Turismo e Lazer | H70: 1214351.3 | I70: São Paulo/SP | J70: DRADS CAPITAL EM SÃO PAULO | K70: Maria Lúcia dos Santos Correia | L70: institutofuturo@uol.com.br | M70: 45322 | N70: Desclassificado | O70: Sem Pendrive | AE70: =AVERAGE(Q70:AD70) -> #DIV/0! | AF70: =IF(AE70>=$AF$1,"APROVADO","REPROVADO") -> #DIV/0!
B71: 574 | C71: 572/23 | D71: Organização | E71: Associação Beneficente da Comunidade Nossa Senhora de Fátima de Bertioga | F71: Nossa Senhora de Fátima - II | G71: Eixo VII: Cultura, Esporte, Turismo e Lazer | H71: 388400 | I71: Bertioga/SP | J71: DRADS BAIXADA SANTISTA EM SANTOS | K71: Protocolo 572/23 | L71: associacao.bertioga@gmail.com | M71: 45322 | N71: Desclassificado | O71: Plano de Trabalho não está Rubricado | AE71: =AVERAGE(Q71:AD71) -> #DIV/0! | AF71: =IF(AE71>=$AF$1,"APROVADO","REPROVADO") -> #DIV/0!
B72: 575 | C72: 573/23 | D72: Organização | E72: Associação Beneficente da Comunidade Nossa Senhora de Fátima de Bertioga | F72: Nossa Senhora de Fátima - I | G72: Eixo VII: Cultura, Esporte, Turismo e Lazer | H72: 342980 | I72: Bertioga/SP | J72: DRADS BAIXADA SANTISTA EM SANTOS | K72: Expedito Antônio dos Santos | L72: associacao.bertioga@gmail.com | M72: 45322 | N72: Desclassificado | O72: Plano de Trabalho não está Rubricado | AE72: =AVERAGE(Q72:AD72) -> #DIV/0! | AF72: =IF(AE72>=$AF$1,"APROVADO","REPROVADO") -> #DIV/0!
B73: 576 | C73: 574/23 | D73: Organização | E73: Instituto Luz do Amanhã | F73: Casa Azul | G73: Eixo I: Promoção, Assistência e Desenvolvimento Social | H73: 161302.98 | I73: São Paulo/SP | J73: DRADS CAPITAL EM SÃO PAULO | K73: Roberto Rodrigues | L73: contato@luzdoamanhã.org | M73: 45322 | N73: Desclassificado | O73: Plano de Trabalho não está Rubricado | AE73: =AVERAGE(Q73:AD73) -> #DIV/0! | AF73: =IF(AE73>=$AF$1,"APROVADO","REPROVADO") -> #DIV/0!
B74: 578 | C74: 576/23 | D74: Organização | E74: Associação Beneficente da Comunidade Nossa Senhora de Fátima de Bertioga | F74: Nossa Senhora de Fátima - III | G74: Eixo VII: Cultura, Esporte, Turismo e Lazer | H74: 356288 | I74: Bertioga/SP | J74: DRADS BAIXADA SANTISTA EM SANTOS | K74: Protocolo 573/23 | L74: associacao.bertioga@gmail.com | M74: 45322 | N74: Desclassificado | O74: Plano de Trabalho não está Rubricado | P74: Plano sem Valor Total | AE74: =AVERAGE(Q74:AD74) -> #DIV/0! | AF74: =IF(AE74>=$AF$1,"APROVADO","REPROVADO") -> #DIV/0!
B75: 579 | C75: 577/23 | D75: Organização | E75: Associação Beneficente Esperança Viva | F75: Reviver - III | G75: Eixo VII: Cultura, Esporte, Turismo e Lazer | H75: 517300 | I75: São Paulo/SP | J75: DRADS CAPITAL EM SÃO PAULO | K75: Anderson Aparecido dos Santos | L75: abeviva@gmail.com | M75: 45322 | N75: Desclassificado | O75: Plano de Trabalho não está Rubricado | AE75: =AVERAGE(Q75:AD75) -> #DIV/0! | AF75: =IF(AE75>=$AF$1,"APROVADO","REPROVADO") -> #DIV/0!
B76: 580 | C76: 578/23 | D76: Organização | E76: Associação Beneficente Esperança Viva | F76: Reviver - II | G76: Eixo VII: Cultura, Esporte, Turismo e Lazer | H76: 472580 | I76: São Paulo/SP | J76: DRADS CAPITAL EM SÃO PAULO | K76: Anderson Aparecido dos Santos | L76: abeviva@gmail.com | M76: 45322 | N76: Desclassificado | O76: Plano de Trabalho não está Rubricado | P76: Divergência no nome do Projeto | AE76: =AVERAGE(Q76:AD76) -> #DIV/0! | AF76: =IF(AE76>=$AF$1,"APROVADO","REPROVADO") -> #DIV/0!
B77: 581 | C77: 579/23 | D77: Organização | E77: Associação Cultural Toca da Onça | F77: Vida é Movimento e Movimento é Vida | G77: Eixo VII: Cultura, Esporte, Turismo e Lazer | H77: 811992.39 | I77: São Paulo/SP | J77: DRADS CAPITAL EM SÃO PAULO | K77: Antonio Luiz de Almeida Francisco | L77: associacaotocadaonca@gmail.com | M77: 45322 | N77: Desclassificado | O77: Plano de Trabalho não está Rubricado | AE77: =AVERAGE(Q77:AD77) -> #DIV/0! | AF77: =IF(AE77>=$AF$1,"APROVADO","REPROVADO") -> #DIV/0!
B78: 582 | C78: 580/23 | D78: Organização | E78: Negritute Futebol Clube | F78: Copa Negritude Master 60 Mais | G78: Eixo VII: Cultura, Esporte, Turismo e Lazer | H78: 780717.03 | I78: São Paulo/SP | J78: DRADS CAPITAL EM SÃO PAULO | K78: José Roberto de Andrade | L78: joser.andrade8@gmail.com | M78: 45322 | N78: Desclassificado | O78: Plano de Trabalho não está Rubricado | AE78: =AVERAGE(Q78:AD78) -> #DIV/0! | AF78: =IF(AE78>=$AF$1,"APROVADO","REPROVADO") -> #DIV/0!
B79: 583 | C79: 581/23 | D79: Organização | E79: Negritute Futebol Clube | F79: Esporte para Todos | G79: Eixo VII: Cultura, Esporte, Turismo e Lazer | H79: 780717.03 | I79: São Paulo/SP | J79: DRADS CAPITAL EM SÃO PAULO | K79: José Roberto de Andrade | L79: joser.andrade8@gmail.com | M79: 45322 | N79: Desclassificado | O79: Plano de Trabalho não está Rubricado | AE79: =AVERAGE(Q79:AD79) -> #DIV/0! | AF79: =IF(AE79>=$AF$1,"APROVADO","REPROVADO") -> #DIV/0!
B80: 584 | C80: 582/23 | D80: Organização | E80: Instituto Mãos e Gratidão | F80: Projeto Mais vida | G80: Eixo II: Sáude | H80: 845957.38 | I80: São Paulo/SP | J80: DRADS CAPITAL EM SÃO PAULO | K80: Wagner de Souza Silva | L80: institutomaosegratidao@gmail.com | M80: 45322 | N80: Desclassificado | O80: Plano de Trabalho não está Rubricado | P80: Divergência de Eixo | AE80: =AVERAGE(Q80:AD80) -> #DIV/0! | AF80: =IF(AE80>=$AF$1,"APROVADO","REPROVADO") -> #DIV/0!
B81: 595 | C81: 593/23 | D81: Organização | E81: Instituto Nelf Ruah | F81: Caminhos da Longevidade III | G81: Eixo VII: Cultura, Esporte, Turismo e Lazer | H81: 367680 | I81: São Paulo/SP | J81: DRADS CAPITAL EM SÃO PAULO | K81: Luiciana Nascimento Tagliari | L81: institutonelfruah@gmail.com | M81: 45322 | N81: Desclassificado | O81: Plano de Trabalho não está Rubricado | AE81: =AVERAGE(Q81:AD81) -> #DIV/0! | AF81: =IF(AE81>=$AF$1,"APROVADO","REPROVADO") -> #DIV/0!
B82: 596 | C82: 594/23 | D82: Prefeitura | E82: Municipal de Guaira | F82: Viver com Qualidade de Vida na Melhor Idade | G82: - | H82: 265000 | I82: Guairá/SP | J82: DRADS BARRETOS | K82: Silmara Aparecida dos Reis Cipriano | L82: dadis@guaira.sp.gov.br | M82: 45322 | N82: Desclassificado | O82: Plano de Trabalho não está Rubricado | AE82: =AVERAGE(Q82:AD82) -> #DIV/0! | AF82: =IF(AE82>=$AF$1,"APROVADO","REPROVADO") -> #DIV/0!
B83: 597 | C83: 595/23 | D83: Organização | E83: União da Fé | F83: Arte em Movimento | G83: Eixo VII: Cultura, Esporte, Turismo e Lazer | H83: 1819351.3 | I83: São Paulo/SP | J83: DRADS CAPITAL EM SÃO PAULO | K83: Felipe Pereira Bruno | L83: prfelipepereira87@gmail.com | M83: 45322 | N83: Desclassificado | O83: Sem Pendrive | AE83: =AVERAGE(Q83:AD83) -> #DIV/0! | AF83: =IF(AE83>=$AF$1,"APROVADO","REPROVADO") -> #DIV/0!
B84: 598 | C84: 596/23 | D84: Organização | E84: Instituto Social Maris | F84: O Tempo não para, vamos Viver a Melhor Idade | G84: Eixo VII: Cultura, Esporte, Turismo e Lazer | H84: 1134197.6 | I84: São Paulo/SP | J84: DRADS CAPITAL EM SÃO PAULO | K84: Izimares | L84: institutosocial.maris@gmail.com | M84: 45322 | N84: Desclassificado | O84: Plano de Trabalho não está Rubricado | AE84: =AVERAGE(Q84:AD84) -> #DIV/0! | AF84: =IF(AE84>=$AF$1,"APROVADO","REPROVADO") -> #DIV/0!
B85: 599 | C85: 597/23 | D85: Organização | E85: Agape | F85: Terceira Idade Cultura e Ação | G85: Eixo VII: Cultura, Esporte, Turismo e Lazer | H85: 1214351.3 | I85: São Paulo/SP | J85: DRADS CAPITAL EM SÃO PAULO | K85: Ricardo Pereira | L85: admagape1@gmail.com | M85: 45322 | N85: Desclassificado | O85: Sem Pendrive | AE85: =AVERAGE(Q85:AD85) -> #DIV/0! | AF85: =IF(AE85>=$AF$1,"APROVADO","REPROVADO") -> #DIV/0!
B86: 600 | C86: 598/23 | D86: Organização | E86: Clube de mães | F86: Cultuta e Arte | G86: Eixo VII: Cultura, Esporte, Turismo e Lazer | H86: 1819351.3 | I86: São Paulo/SP | J86: DRADS CAPITAL EM SÃO PAULO | K86: Maria de Fatima de Sousa dos Santos | L86: correialsantos@gmail.com | M86: 45322 | N86: Desclassificado | O86: Sem Pendrive | AE86: =AVERAGE(Q86:AD86) -> #DIV/0! | AF86: =IF(AE86>=$AF$1,"APROVADO","REPROVADO") -> #DIV/0!
B87: 601 | C87: 599/23 | D87: Organização | E87: Projeto Missão Amar em Cristo | F87: Terceira Idade em Movimento | G87: Eixo VII: Cultura, Esporte, Turismo e Lazer | H87: 1214351.3 | I87: São Paulo/SP | J87: DRADS CAPITAL EM SÃO PAULO | K87: Andre Aparecida Santos Quintiliano Oliveira | L87: acmeireli@gmail.com | M87: 45322 | N87: Desclassificado | O87: Sem Pendrive | AE87: =AVERAGE(Q87:AD87) -> #DIV/0! | AF87: =IF(AE87>=$AF$1,"APROVADO","REPROVADO") -> #DIV/0!
B88: 602 | C88: 600/23 | D88: Organização | E88: União Popular de Moradia Adão Manoel da Silva | F88: Nucleo de Convivio Social para Idosos "Carpe Diem" | G88: Eixo I: Promoção, Assistência e Desenvolvimento Social | H88: 2500000 | I88: São Paulo/SP | J88: DRADS CAPITAL EM SÃO PAULO | K88: Vera Lucia Alves | L88: recursoshumanosadaomanoel@hotmail.com | M88: 45322 | N88: Desclassificado | O88: Plano de Trabalho não está Rubricado | AE88: =AVERAGE(Q88:AD88) -> #DIV/0! | AF88: =IF(AE88>=$AF$1,"APROVADO","REPROVADO") -> #DIV/0!
B89: 606 | C89: 604/23 | D89: Prefeitura | E89: Municipal de Osasco | F89: Projeto: Fala Musical | G89: Eixo I: Promoção, Assistência e Desenvolvimento Social | H89: 91992 | I89: Osasco/SP | J89: DRADS SPO EM OSASCO | K89: Rogério Lins Wanderley | L89: gabinete.sas@osasco.sp.gov.br | M89: 45322 | N89: Desclassificado | O89: Plano de Trabalho não está Rubricado | AE89: =AVERAGE(Q89:AD89) -> #DIV/0! | AF89: =IF(AE89>=$AF$1,"APROVADO","REPROVADO") -> #DIV/0!
B90: 607 | C90: 605/23 | D90: Prefeitura | E90: Municipal de Osasco | F90: Aprender para Melhor Cuidar | G90: Eixo III: Educação | H90: 184320 | I90: Osasco/SP | J90: DRADS SPO EM OSASCO | K90: Rogério Lins Wanderley | L90: gabinete.sas@osasco.sp.gov.br | M90: 45322 | N90: Desclassificado | O90: Plano de Trabalho não está Rubricado | AE90: =AVERAGE(Q90:AD90) -> #DIV/0! | AF90: =IF(AE90>=$AF$1,"APROVADO","REPROVADO") -> #DIV/0!
...

Sheet Reprovados
AF1: 204
B2: CONSELHO ESTADUAL DO IDOSO Rua Boa Vista, 170- CEP 01204-001 - São Paulo-SP Fone 11-2763-8122/2763-8035 cei@desenvolvimentosocial.sp.gov.br
B3: ORGANIZAÇÕES SOCIAIS
C4: Protocolo | D4: OSC/Prefeitura | E4: NOME DO PROPONENTE | F4: NOME DO PROJETO | G4: EIXO | H4: VALOR TOTAL DO PROJETO | I4: MUNICÍPIO | J4: DRADS | K4: Responsável - OSC | L4: EMAIL | M4: ENTREGUE DIA | N4: ETAPA da Análise | O4: PENDÊNCIA | P4: OBS | Q4: NOTA Gilberto | R4: NOTA Erica | S4: NOTA Enizal | T4: NOTA Walkyria | U4: NOTA Elisete | V4: NOTA Adriano | W4: NOTA Paulo Albano | X4: NOTA Alexandra | Y4: NOTA Priscila | Z4: NOTA Leila | AA4: NOTA Vanise | AB4: NOTA Jeverson | AC4: NOTA Cristiane | AD4: NOTA Márcio | AE4: Média | AF4: RESULTADO FINAL
B5: 30 | C5: 030/23 | D5: Prefeitura | E5: Municipal de Bastos | F5: Idoso em Movimento | G5: Eixo I: Promoção, Assistência e Desenvolvimento Social | H5: 610060.4 | I5: Bastos/SP | J5: DRADS MARÍLIA | K5: Luzia Kiyoko Honda | L5: semas@riopreto.sp.gov.br | M5: 45303 | N5: Reprovado | O5: Edital não Contempla Aquisição de Veiculo | Q5: 0 | R5: 29 | S5: 44 | AE5: =AVERAGE(Q5:AD5) -> 24.333333 | AF5: =IF(AE5>=$AF$1,"APROVADO","REPROVADO") -> REPROVADO
B6: 31 | C6: 031/23 | D6: Prefeitura | E6: Municipal de Bastos | F6: Longevidade Ativa e Protegida | G6: Eixo I: Promoção, Assistência e Desenvolvimento Social | H6: 160528.4 | I6: Bastos/SP | J6: DRADS MARÍLIA | K6: Luzia Kiyoko Honda | L6: pmbab@Bastos.sp.gov.br | M6: 45303 | N6: Reprovado | O6: Edital não Contempla Aquisição de Veiculo | Q6: 0 | R6: 169 | S6: 195 | T6: 206 | AE6: =AVERAGE(Q6:AD6) -> 142.5 | AF6: =IF(AE6>=$AF$1,"APROVADO","REPROVADO") -> REPROVADO
B7: 38 | C7: 038/23 | D7: Organização | E7: Lar Fraterno São Vicente de Apiaí | F7: Mais conforto | G7: Eixo II: Sáude | H7: 180000 | I7: Apiaí/SP | J7: DRADS ITAPEVA | K7: Alaíme Yuki monteiro Takiguchi Correa | L7: asiloapiai@hotmail.com | M7: 45303 | N7: Reprovado | O7: Faltou Preencher os Itens ns° 6, 10,11 e 12 do Plano de Trabalho | Q7: 332 | S7: 200 | T7: 0 | AE7: =AVERAGE(Q7:AD7) -> 177.33333 | AF7: =IF(AE7>=$AF$1,"APROVADO","REPROVADO") -> REPROVADO
B8: 50 | C8: 050/23 | D8: Prefeitura | E8: Municipal de Nantes | F8: Bem Estar na Melhor Idade | G8: Eixo I: Promoção, Assistência e Desenvolvimento Social | H8: 331000 | I8: Nantes/SP | J8: DRADS ALTA SOROCABANA EM PRESIDENTE PRUDENTE | K8: Aline Fernanda de Jesus Souza | L8: protecaosocialespecial@votuporanga.sp.gov.br | M8: 45303 | N8: Reprovado | O8: Edital não Contempla Aquisição de Veiculo | Q8: 0 | R8: 188 | S8: 243 | T8: 0 | AE8: =AVERAGE(Q8:AD8) -> 107.75 | AF8: =IF(AE8>=$AF$1,"APROVADO","REPROVADO") -> REPROVADO
